Workbook

Sheet Accueil
A4: FICHE DE SUIVI DE STOCKS
A7: Dépôt Vrac
A9: Bouteille HS | C9: Bouteille Neuve | E9: STOCK OUTILS_CE
A12: Centre emplisseur
A14: Bouteille Consigne | C14: Bouteille Réépreuve | E14: Bouteille Peinture

Sheet Btles Neuve _ DV
B1: SAEPP | K1: Année: 2026 | R1: Menu
B3: FICHE DE SUIVI DE STOCKS | G3: BOUTEILLES NEUVES - DEPOT VRAC | Q3: MOIS : | R3: =TEXT(TODAY(),"mmmm") -> janvier
G5: B6 | J5: INVENTAIRE | N5: B12 | Q5: INVENTAIRE
B6: DATE | C6: TYPE DE MVT | D6: Bon | E6: OPERATIONS | F6: DESTINATION / PROVENANCE | G6: QUANTITE | H6: QUANTITE STOCK FINAL | J6: INVENTAIRE | K6: ECART | N6: QUANTITE | O6: QUANTITE STOCK FINAL | Q6: INVENTAIRE | R6: ECART
B8: BOUTEILLES NEUVES - PI
B9: JANVIER 2026 | I9: 6145 | K9: =IF(J9="","",J9-H9) | R9: =IF(Q9="","",Q9-O9)
B10: 46024 | C10: Entrée | E10: INVENTAIRE | H10: 0 | J10: 0 | K10: =IF(J10="","",J10-H10) -> 0 | O10: 0 | Q10: 0 | R10: =IF(Q10="","",Q10-O10) -> 0
B11: 46024 | C11: Entrée | E11: BTLE NEUVES | G11: 2240 | H11: =IF(C11="","",IF(C11="Entrée",H10+G11,IF(C11="Sortie",H10-G11))) -> 2240 | J11: 2240 | K11: =IF(J11="","",J11-H11) -> 0 | O11: 0
B12: 46025 | C12: Entrée | E12: INVENTAIRE | H12: =IF(C12="","",IF(C12="Entrée",H11+G12,IF(C12="Sortie",H11-G12))) -> 2240 | K12: =IF(J12="","",J12-H12) | O12: 0 | R12: =IF(Q12="","",Q12-O12)
B13: 46025 | C13: Sortie | E13: SORTIE CONSIGNE | G13: 700 | H13: =IF(C13="","",IF(C13="Entrée",H12+G13,IF(C13="Sortie",H12-G13))) -> 1540 | K13: =IF(J13="","",J13-H13) | O13: 0 | R13: =IF(Q13="","",Q13-O13)
B14: 46025 | C14: Sortie | E14: SORTIE CONSIGNE | G14: 700 | H14: =IF(C14="","",IF(C14="Entrée",H13+G14,IF(C14="Sortie",H13-G14))) -> 840 | K14: =IF(J14="","",J14-H14) | O14: 0 | R14: =IF(Q14="","",Q14-O14)
B15: 46025 | C15: Sortie | E15: SORTIE CONSIGNE | G15: 700 | H15: =IF(C15="","",IF(C15="Entrée",H14+G15,IF(C15="Sortie",H14-G15))) -> 140 | K15: =IF(J15="","",J15-H15) | O15: =IF(C15="","",IF(C15="Entrée",O14+N15,IF(C15="Sortie",O14-N15))) -> 0 | R15: =IF(Q15="","",Q15-O15)
B16: 46026 | C16: Entrée | E16: INVENTAIRE | H16: =IF(C16="","",IF(C16="Entrée",H15+G16,IF(C16="Sortie",H15-G16))) -> 140 | J16: 140 | K16: =IF(J16="","",J16-H16) -> 0 | O16: =IF(C16="","",IF(C16="Entrée",O15+N16,IF(C16="Sortie",O15-N16))) -> 0 | R16: =IF(Q16="","",Q16-O16)
B17: 46027 | C17: Entrée | E17: INVENTAIRE | H17: =IF(C17="","",IF(C17="Entrée",H16+G17,IF(C17="Sortie",H16-G17))) -> 140 | J17: 140 | K17: =IF(J17="","",J17-H17) -> 0 | O17: =IF(C17="","",IF(C17="Entrée",O16+N17,IF(C17="Sortie",O16-N17))) -> 0 | R17: =IF(Q17="","",Q17-O17)
H18: =IF(C18="","",IF(C18="Entrée",H17+G18,IF(C18="Sortie",H17-G18))) | K18: =IF(J18="","",J18-H18) | O18: =IF(C18="","",IF(C18="Entrée",O17+N18,IF(C18="Sortie",O17-N18))) | R18: =IF(Q18="","",Q18-O18)
H19: =IF(C19="","",IF(C19="Entrée",H18+G19,IF(C19="Sortie",H18-G19))) | K19: =IF(J19="","",J19-H19) | O19: =IF(C19="","",IF(C19="Entrée",O18+N19,IF(C19="Sortie",O18-N19))) | R19: =IF(Q19="","",Q19-O19)
H20: =IF(C20="","",IF(C20="Entrée",#REF!+G20,IF(C20="Sortie",#REF!-G20))) | K20: =IF(J20="","",J20-H20) | O20: =IF(C20="","",IF(J20="Entrée",#REF!+N20,IF(J20="Sortie",#REF!-N20))) | R20: =IF(Q20="","",Q20-O20)
F22: Cumul Entrée PI : | G22: =SUMIF(C9:C20,"Entrée",G9:G20) -> 2240 | Q22: Cumul Entrée B12 PI : | R22: =SUMIF(C9:C20,"Entrée",N9:N20) -> 0
F23: Cumul Sortie PI : | G23: =SUMIF(C9:C20,"Sortie",G9:G20) -> 2100 | Q23: Cumul Sortie B12 PI : | R23: =SUMIF(C9:C20,"Sortie",N9:N20) -> 0
G27: B6 | J27: INVENTAIRE | N27: B12 | Q27: INVENTAIRE
B28: DATE | C28: TYPE DE MVT | D28: Bon | E28: OPERATIONS | F28: PROVENANCE / DESTINATION | G28: QUANTITE | H28: QUANTITE STOCK FINAL | J28: INVENTAIRE | K28: ECART | N28: QUANTITE | O28: QUANTITE STOCK FINAL | Q28: INVENTAIRE | R28: ECART
B30: BOUTEILLES NEUVES - TEMCI
B31: NOVEMBRE 2025 | K31: =IF(J31="","",J31-H31) | R31: =IF(Q31="","",Q31-O31)
B32: 46024 | C32: Entrée | E32: INVENTAIRE | H32: 24687 | J32: 24687 | K32: =IF(J32="","",J32-H32) -> 0 | O32: 2161 | Q32: 2161 | R32: =IF(Q32="","",Q32-O32) -> 0
B33: 46025 | C33: Entrée | E33: INVENTAIRE | H33: =IF(C33="","",IF(C33="Entrée",H32+G33,IF(C33="Sortie",H32-G33))) -> 24687 | J33: 24687 | K33: =IF(J33="","",J33-H33) -> 0 | O33: =IF(C33="","",IF(C33="Entrée",O32+N33,IF(C33="Sortie",O32-N33))) -> 2161 | Q33: 2161 | R33: =IF(Q33="","",Q33-O33) -> 0
B34: 46026 | C34: Entrée | E34: INVENTAIRE | H34: =IF(C34="","",IF(C34="Entrée",H33+G34,IF(C34="Sortie",H33-G34))) -> 24687 | J34: 24687 | K34: =IF(J34="","",J34-H34) -> 0 | O34: =IF(C34="","",IF(C34="Entrée",O33+N34,IF(C34="Sortie",O33-N34))) -> 2161 | Q34: 2161 | R34: =IF(Q34="","",Q34-O34) -> 0
B35: 46027 | C35: Entrée | E35: INVENTAIRE | H35: =IF(C35="","",IF(C35="Entrée",H34+G35,IF(C35="Sortie",H34-G35))) -> 24687 | J35: 24687 | K35: =IF(J35="","",J35-H35) -> 0 | O35: =IF(C35="","",IF(C35="Entrée",O34+N35,IF(C35="Sortie",O34-N35))) -> 2161 | Q35: 2161 | R35: =IF(Q35="","",Q35-O35) -> 0
H36: =IF(C36="","",IF(C36="Entrée",H35+G36,IF(C36="Sortie",H35-G36))) | K36: =IF(J36="","",J36-H36) | O36: =IF(C36="","",IF(C36="Entrée",O35+N36,IF(C36="Sortie",O35-N36))) | R36: =IF(Q36="","",Q36-O36)
H37: =IF(C37="","",IF(C37="Entrée",#REF!+G37,IF(C37="Sortie",#REF!-G37))) | K37: =IF(J37="","",J37-H37) | O37: =IF(C37="","",IF(C37="Entrée",#REF!+N37,IF(C37="Sortie",#REF!-N37))) | R37: =IF(Q37="","",Q37-O37)
H38: =IF(C38="","",IF(C38="Entrée",H37+G38,IF(C38="Sortie",H37-G38))) | K38: =IF(J38="","",J38-H38) | O38: =IF(C38="","",IF(C38="Entrée",O37+N38,IF(C38="Sortie",O37-N38))) | R38: =IF(Q38="","",Q38-O38)
H39: =IF(C39="","",IF(C39="Entrée",H38+G39,IF(C39="Sortie",H38-G39))) | K39: =IF(J39="","",J39-H39) | O39: =IF(C39="","",IF(C39="Entrée",O38+N39,IF(C39="Sortie",O38-N39))) | R39: =IF(Q39="","",Q39-O39)
H40: =IF(C40="","",IF(C40="Entrée",#REF!+G40,IF(C40="Sortie",#REF!-G40))) | K40: =IF(J40="","",J40-H40) | O40: =IF(C40="","",IF(C40="Entrée",#REF!+N40,IF(C40="Sortie",#REF!-N40))) | R40: =IF(Q40="","",Q40-O40)
F42: Cumul Entrée B6 TEMCI : | G42: =SUMIF(C31:C40,"Entrée",G31:G40) -> 0 | Q42: Cumul Entrée B12 TEMCI : | R42: =SUMIF(C31:C40,"Entrée",N31:N40) -> 0
F43: Cumul Sortie B6 TEMCI : | G43: =SUMIF(C31:C40,"Sortie",G31:G40) -> 0 | Q43: Cumul Sortie B12 TEMCI : | R43: =SUMIF(C31:C40,"Sortie",N31:N40) -> 0
G46: B6 | J46: INVENTAIRE | N46: B12 | Q46: INVENTAIRE
B47: DATE | C47: TYPE DE MVT | D47: Bon | E47: OPERATIONS | F47: PROVENANCE / DESTINATION | G47: QUANTITE | H47: QUANTITE STOCK FINAL | J47: INVENTAIRE | K47: ECART | N47: QUANTITE | O47: QUANTITE STOCK FINAL | Q47: INVENTAIRE | R47: ECART
B49: BOUTEILLES NEUVES - VIVO ENERGY
B50: NOVEMBRE 2025 | K50: =IF(J50="","",J50-H50) | R50: =IF(Q50="","",Q50-O50)
B51: 45931 | C51: Entrée | E51: INVENTAIRE | H51: 0 | J51: 0 | K51: =IF(J51="","",J51-H51) -> 0 | O51: 0 | R51: =IF(Q51="","",Q51-O51)
B52: 45932 | C52: Entrée | E52: INVENTAIRE | H52: =IF(C52="","",IF(C52="Entrée",H51+G52,IF(C52="Sortie",H51-G52))) -> 0 | K52: =IF(J52="","",J52-H52) | O52: =IF(C52="","",IF(C52="Entrée",O51+N52,IF(C52="Sortie",O51-N52))) -> 0 | R52: =IF(Q52="","",Q52-O52)
...

Sheet Btles HS _ DV
B1: SAEPP | K1: Année: 2025 | R1: Menu
B3: FICHE DE SUIVI DE STOCKS | G3: BOUTEILLES HS - DEPOT VRAC | Q3: MOIS : | R3: =TEXT(TODAY(),"mmmm") -> janvier
G5: B6 | J5: INVENTAIRE | N5: B12 | Q5: INVENTAIRE
B6: DATE | C6: TYPE DE MVT | D6: Bon | E6: OPERATIONS | F6: DESTINATION / PROVENANCE | G6: QUANTITE | H6: QUANTITE STOCK FINAL | J6: INVENTAIRE | K6: ECART | N6: QUANTITE | O6: QUANTITE STOCK FINAL | Q6: INVENTAIRE | R6: ECART
B8: BOUTEILLES HS - PI
B9: JANVIER 2026 | K9: =IF(J9="","",J9-H9) | R9: =IF(Q9="","",Q9-O9)
B10: 46024 | C10: Entrée | E10: INVENTAIRE | H10: =16216+85 -> 16301 | J10: 16301 | K10: =IF(J10="","",J10-H10) -> 0 | O10: 1128 | P10: =O10 -> 1128 | Q10: =P10 -> 1128 | R10: =IF(Q10="","",Q10-O10) -> 0
B11: 46025 | C11: Entrée | E11: INVENTAIRE | H11: =IF(C11="","",IF(C11="Entrée",H10+G11,IF(C11="Sortie",H10-G11))) -> 16301 | J11: 16301 | K11: =IF(J11="","",J11-H11) -> 0 | O11: =IF(C11="","",IF(C11="Entrée",O10+N11,IF(C11="Sortie",O10-N11))) -> 1128 | P11: =O11 -> 1128 | Q11: =P11 -> 1128 | R11: =IF(Q11="","",Q11-O11) -> 0
B12: 46025 | C12: Entrée | D12: 110 | E12: ENTRER HS | G12: 770 | H12: =IF(C12="","",IF(C12="Entrée",H11+G12,IF(C12="Sortie",H11-G12))) -> 17071 | K12: =IF(J12="","",J12-H12) | N12: 70 | O12: =IF(C12="","",IF(C12="Entrée",O11+N12,IF(C12="Sortie",O11-N12))) -> 1198 | R12: =IF(Q12="","",Q12-O12)
B13: 46026 | C13: Entrée | E13: INVENTAIRE | H13: =IF(C13="","",IF(C13="Entrée",H12+G13,IF(C13="Sortie",H12-G13))) -> 17071 | K13: =IF(J13="","",J13-H13) | O13: =IF(C13="","",IF(C13="Entrée",O12+N13,IF(C13="Sortie",O12-N13))) -> 1198 | R13: =IF(Q13="","",Q13-O13)
B14: 46027 | C14: Entrée | E14: INVENTAIRE | H14: =IF(C14="","",IF(C14="Entrée",H13+G14,IF(C14="Sortie",H13-G14))) -> 17071 | J14: =16986+85 -> 17071 | K14: =IF(J14="","",J14-H14) -> 0 | O14: =IF(C14="","",IF(C14="Entrée",O13+N14,IF(C14="Sortie",O13-N14))) -> 1198 | Q14: =966+209+23 -> 1198 | R14: =IF(Q14="","",Q14-O14) -> 0
K15: =IF(J15="","",J15-H15) | R15: =IF(Q15="","",Q15-O15)
K16: =IF(J16="","",J16-H16) | R16: =IF(Q16="","",Q16-O16)
K17: =IF(J17="","",J17-H17) | R17: =IF(Q17="","",Q17-O17)
K18: =IF(J18="","",J18-H18) | R18: =IF(Q18="","",Q18-O18)
H19: =IF(C19="","",IF(C19="Entrée",H12+G19,IF(C19="Sortie",H12-G19))) | K19: =IF(J19="","",J19-H19) | O19: =IF(C19="","",IF(C19="Entrée",O12+N19,IF(C19="Sortie",O12-N19))) | R19: =IF(Q19="","",Q19-O19)
H20: =IF(C20="","",IF(C20="Entrée",H19+G20,IF(C20="Sortie",H19-G20))) | K20: =IF(J20="","",J20-H20) | O20: =IF(C20="","",IF(C20="Entrée",O19+N20,IF(C20="Sortie",O19-N20))) | R20: =IF(Q20="","",Q20-O20)
H21: =IF(C21="","",IF(C21="Entrée",#REF!+G21,IF(C21="Sortie",#REF!-G21))) | K21: =IF(J21="","",J21-H21) | O21: =IF(C21="","",IF(J21="Entrée",#REF!+N21,IF(J21="Sortie",#REF!-N21))) | R21: =IF(Q21="","",Q21-O21)
R22: =IF(Q22="","",Q22-O22)
F23: Cumul Entrée PI : | G23: =SUMIF(C9:C21,"Entrée",G9:G21) -> 770 | Q23: Cumul Entrée B12 PI : | R23: =SUMIF(C9:C21,"Entrée",N9:N21) -> 70
F24: Cumul Sortie PI : | G24: =SUMIF(C9:C21,"Sortie",G9:G21) -> 0 | Q24: Cumul Sortie B12 PI : | R24: =SUMIF(C9:C21,"Sortie",N9:N21) -> 0
B25: * HS : Hors Service
G28: B6 | J28: INVENTAIRE | N28: B12 | Q28: INVENTAIRE
B29: DATE | C29: TYPE DE MVT | D29: Bon | E29: OPERATIONS | F29: PROVENANCE / DESTINATION | G29: QUANTITE | H29: QUANTITE STOCK FINAL | J29: INVENTAIRE | K29: ECART | N29: QUANTITE | O29: QUANTITE STOCK FINAL | Q29: INVENTAIRE | R29: ECART
B31: BOUTEILLES HS - TEMCI
B32: JANVIER 2026 | K32: =IF(J32="","",J32-H32) | R32: =IF(Q32="","",Q32-O32)
B33: 46024 | C33: Entrée | E33: INVENTAIRE | H33: 1708 | J33: =+H33 -> 1708 | K33: =IF(J33="","",J33-H33) -> 0 | O33: 925 | Q33: =+O33 -> 925 | R33: =IF(Q33="","",Q33-O33) -> 0
B34: 46025 | C34: Entrée | E34: INVENTAIRE | H34: =IF(C34="","",IF(C34="Entrée",H33+G34,IF(C34="Sortie",H33-G34))) -> 1708 | J34: =+H34 -> 1708 | K34: =IF(J34="","",J34-H34) -> 0 | O34: =IF(C34="","",IF(C34="Entrée",O33+N34,IF(C34="Sortie",O33-N34))) -> 925 | Q34: =+O34 -> 925 | R34: =IF(Q34="","",Q34-O34) -> 0
A35: E | B35: 46025 | C35: Entrée | D35: 111 | E35: ENTRER HS | G35: 266 | H35: =IF(C35="","",IF(C35="Entrée",H34+G35,IF(C35="Sortie",H34-G35))) -> 1974 | K35: =IF(J35="","",J35-H35) | N35: 252 | O35: =IF(C35="","",IF(C35="Entrée",O34+N35,IF(C35="Sortie",O34-N35))) -> 1177 | R35: =IF(Q35="","",Q35-O35)
B36: 46026 | C36: Entrée | E36: INVENTAIRE | H36: =IF(C36="","",IF(C36="Entrée",H35+G36,IF(C36="Sortie",H35-G36))) -> 1974 | K36: =IF(J36="","",J36-H36) | O36: =IF(C36="","",IF(C36="Entrée",O35+N36,IF(C36="Sortie",O35-N36))) -> 1177 | R36: =IF(Q36="","",Q36-O36)
B37: 46027 | C37: Entrée | E37: INVENTAIRE | H37: =IF(C37="","",IF(C37="Entrée",H36+G37,IF(C37="Sortie",H36-G37))) -> 1974 | J37: =1762+212 -> 1974 | K37: =IF(J37="","",J37-H37) -> 0 | O37: =IF(C37="","",IF(C37="Entrée",O36+N37,IF(C37="Sortie",O36-N37))) -> 1177 | Q37: =1060+35+82 -> 1177 | R37: =IF(Q37="","",Q37-O37) -> 0
H38: =IF(C38="","",IF(C38="Entrée",H37+G38,IF(C38="Sortie",H37-G38))) | K38: =IF(J38="","",J38-H38) | O38: =IF(C38="","",IF(C38="Entrée",O37+N38,IF(C38="Sortie",O37-N38))) | R38: =IF(Q38="","",Q38-O38)
H39: =IF(C39="","",IF(C39="Entrée",H38+G39,IF(C39="Sortie",H38-G39))) | K39: =IF(J39="","",J39-H39) | O39: =IF(C39="","",IF(C39="Entrée",O38+N39,IF(C39="Sortie",O38-N39))) | R39: =IF(Q39="","",Q39-O39)
H40: =IF(C40="","",IF(C40="Entrée",H39+G40,IF(C40="Sortie",H39-G40))) | K40: =IF(J40="","",J40-H40) | O40: =IF(C40="","",IF(C40="Entrée",O39+N40,IF(C40="Sortie",O39-N40))) | R40: =IF(Q40="","",Q40-O40)
H41: =IF(C41="","",IF(C41="Entrée",H40+G41,IF(C41="Sortie",H40-G41))) | K41: =IF(J41="","",J41-H41) | O41: =IF(C41="","",IF(C41="Entrée",O40+N41,IF(C41="Sortie",O40-N41))) | R41: =IF(Q41="","",Q41-O41)
H42: =IF(C42="","",IF(C42="Entrée",#REF!+G42,IF(C42="Sortie",#REF!-G42))) | K42: =IF(J42="","",J42-H42) | O42: =IF(C42="","",IF(C42="Entrée",#REF!+N42,IF(C42="Sortie",#REF!-N42))) | R42: =IF(Q42="","",Q42-O42)
F44: Cumul Entrée B6 TEMCI : | G44: =SUMIF(C32:C42,"Entrée",G32:G42) -> 266 | Q44: Cumul Entrée B12 TEMCI : | R44: =SUMIF(C32:C42,"Entrée",N32:N42) -> 252
F45: Cumul Sortie B6 TEMCI : | G45: =SUMIF(C32:C42,"Sortie",G32:G42) -> 0 | Q45: Cumul Sortie B12 TEMCI : | R45: =SUMIF(C32:C42,"Sortie",N32:N42) -> 0
B46: * HS : Hors Service

Sheet RECONFIGURATION
B1: SAEPP | K1: Année: 2025 | R1: Menu
B3: FICHE DE SUIVI DE STOCKS | F3: BOUTEILLES RECONFIGURATIOB/MANDATAIRE - DEPOT VRAC | Q3: MOIS : | R3: =TEXT(TODAY(),"mmmm") -> janvier
G5: B6 | J5: INVENTAIRE | N5: B12 | Q5: INVENTAIRE
B6: DATE | C6: TYPE DE MVT | D6: Bon | E6: OPERATIONS | F6: DESTINATION / PROVENANCE | G6: QUANTITE | H6: QUANTITE STOCK FINAL | J6: INVENTAIRE | K6: ECART | N6: QUANTITE | O6: QUANTITE STOCK FINAL | Q6: INVENTAIRE | R6: ECART
B8: BOUTEILLES HS - PI
B9: NOVEMBRE 2025 | K9: =IF(J9="","",J9-H9) | R9: =IF(Q9="","",Q9-O9)
B10: 45931 | C10: Entrée | E10: INVENTAIRE | H10: =248+2758 -> 3006 | J10: =+H10 -> 3006 | K10: =IF(J10="","",J10-H10) -> 0 | O10: =334+200+105 -> 639 | P10: =O10 -> 639 | Q10: =P10 -> 639 | R10: =IF(Q10="","",Q10-O10) -> 0
H11: =IF(C11="","",IF(C11="Entrée",H10+G11,IF(C11="Sortie",H10-G11))) | K11: =IF(J11="","",J11-H11) | O11: =IF(C11="","",IF(C11="Entrée",O10+N11,IF(C11="Sortie",O10-N11))) | R11: =IF(Q11="","",Q11-O11)
H12: =IF(C12="","",IF(C12="Entrée",H11+G12,IF(C12="Sortie",H11-G12))) | K12: =IF(J12="","",J12-H12) | O12: =IF(C12="","",IF(C12="Entrée",O11+N12,IF(C12="Sortie",O11-N12))) | R12: =IF(Q12="","",Q12-O12)
H13: =IF(C13="","",IF(C13="Entrée",H12+G13,IF(C13="Sortie",H12-G13))) | K13: =IF(J13="","",J13-H13) | O13: =IF(C13="","",IF(C13="Entrée",O12+N13,IF(C13="Sortie",O12-N13))) | R13: =IF(Q13="","",Q13-O13)
H14: =IF(C14="","",IF(C14="Entrée",H13+G14,IF(C14="Sortie",H13-G14))) | K14: =IF(J14="","",J14-H14) | O14: =IF(C14="","",IF(C14="Entrée",O13+N14,IF(C14="Sortie",O13-N14))) | R14: =IF(Q14="","",Q14-O14)
H15: =IF(C15="","",IF(C15="Entrée",#REF!+G15,IF(C15="Sortie",#REF!-G15))) | K15: =IF(J15="","",J15-H15) | O15: =IF(C15="","",IF(J15="Entrée",#REF!+N15,IF(J15="Sortie",#REF!-N15))) | R15: =IF(Q15="","",Q15-O15)
R16: =IF(Q16="","",Q16-O16)
F17: Cumul Entrée PI : | G17: =SUMIF(C9:C15,"Entrée",G9:G15) -> 0 | Q17: Cumul Entrée B12 PI : | R17: =SUMIF(C9:C15,"Entrée",N9:N15) -> 0
F18: Cumul Sortie PI : | G18: =SUMIF(C9:C15,"Sortie",G9:G15) -> 0 | Q18: Cumul Sortie B12 PI : | R18: =SUMIF(C9:C15,"Sortie",N9:N15) -> 0
B19: * HS : Hors Service
G22: B6 | J22: INVENTAIRE | N22: B12 | Q22: INVENTAIRE
B23: DATE | C23: TYPE DE MVT | D23: Bon | E23: OPERATIONS | F23: PROVENANCE / DESTINATION | G23: QUANTITE | H23: QUANTITE STOCK FINAL | J23: INVENTAIRE | K23: ECART | N23: QUANTITE | O23: QUANTITE STOCK FINAL | Q23: INVENTAIRE | R23: ECART
B25: BOUTEILLES HS - TEMCI
B26: NOVEMBRE 2025 | K26: =IF(J26="","",J26-H26) | R26: =IF(Q26="","",Q26-O26)
B27: 45931 | E27: INVENTAIRE | H27: =945+1945 -> 2890 | J27: =+H27 -> 2890 | K27: =IF(J27="","",J27-H27) -> 0 | O27: =132+193 -> 325 | Q27: =+O27 -> 325 | R27: =IF(Q27="","",Q27-O27) -> 0
H28: =IF(C28="","",IF(C28="Entrée",H27+G28,IF(C28="Sortie",H27-G28))) | K28: =IF(J28="","",J28-H28) | O28: =IF(C28="","",IF(C28="Entrée",O27+N28,IF(C28="Sortie",O27-N28))) | R28: =IF(Q28="","",Q28-O28)
A29: E | H29: =IF(C29="","",IF(C29="Entrée",H28+G29,IF(C29="Sortie",H28-G29))) | K29: =IF(J29="","",J29-H29) | O29: =IF(C29="","",IF(C29="Entrée",O28+N29,IF(C29="Sortie",O28-N29))) | R29: =IF(Q29="","",Q29-O29)
H30: =IF(C30="","",IF(C30="Entrée",H29+G30,IF(C30="Sortie",H29-G30))) | K30: =IF(J30="","",J30-H30) | O30: =IF(C30="","",IF(C30="Entrée",O29+N30,IF(C30="Sortie",O29-N30))) | R30: =IF(Q30="","",Q30-O30)
H31: =IF(C31="","",IF(C31="Entrée",H30+G31,IF(C31="Sortie",H30-G31))) | K31: =IF(J31="","",J31-H31) | O31: =IF(C31="","",IF(C31="Entrée",O30+N31,IF(C31="Sortie",O30-N31))) | R31: =IF(Q31="","",Q31-O31)
H32: =IF(C32="","",IF(C32="Entrée",H31+G32,IF(C32="Sortie",H31-G32))) | K32: =IF(J32="","",J32-H32) | O32: =IF(C32="","",IF(C32="Entrée",O31+N32,IF(C32="Sortie",O31-N32))) | R32: =IF(Q32="","",Q32-O32)
H33: =IF(C33="","",IF(C33="Entrée",H32+G33,IF(C33="Sortie",H32-G33))) | K33: =IF(J33="","",J33-H33) | O33: =IF(C33="","",IF(C33="Entrée",O32+N33,IF(C33="Sortie",O32-N33))) | R33: =IF(Q33="","",Q33-O33)
H34: =IF(C34="","",IF(C34="Entrée",H33+G34,IF(C34="Sortie",H33-G34))) | K34: =IF(J34="","",J34-H34) | O34: =IF(C34="","",IF(C34="Entrée",O33+N34,IF(C34="Sortie",O33-N34))) | R34: =IF(Q34="","",Q34-O34)
H35: =IF(C35="","",IF(C35="Entrée",H34+G35,IF(C35="Sortie",H34-G35))) | K35: =IF(J35="","",J35-H35) | O35: =IF(C35="","",IF(C35="Entrée",O34+N35,IF(C35="Sortie",O34-N35))) | R35: =IF(Q35="","",Q35-O35)
H36: =IF(C36="","",IF(C36="Entrée",#REF!+G36,IF(C36="Sortie",#REF!-G36))) | K36: =IF(J36="","",J36-H36) | O36: =IF(C36="","",IF(C36="Entrée",#REF!+N36,IF(C36="Sortie",#REF!-N36))) | R36: =IF(Q36="","",Q36-O36)
F38: Cumul Entrée B6 TEMCI : | G38: =SUMIF(C26:C36,"Entrée",G26:G36) -> 0 | Q38: Cumul Entrée B12 TEMCI : | R38: =SUMIF(C26:C36,"Entrée",N26:N36) -> 0
F39: Cumul Sortie B6 TEMCI : | G39: =SUMIF(C26:C36,"Sortie",G26:G36) -> 0 | Q39: Cumul Sortie B12 TEMCI : | R39: =SUMIF(C26:C36,"Sortie",N26:N36) -> 0
B40: * HS : Hors Service

Sheet Consigne _ CE
B1: SAEPP | K1: Année: 2026 | R1: Menu
B3: FICHE DE SUIVI DE STOCKS | F3: BOUTEILLES CONSIGNES - CENTRE EMPLISSEUR | Q3: MOIS : | R3: =TEXT(TODAY(),"mmmm") -> janvier
G5: B6 | J5: INVENTAIRE | N5: B12 | Q5: INVENTAIRE
B6: DATE | C6: TYPE DE MVT | D6: Bon | E6: OPERATIONS | F6: DESTINATION / PROVENANCE | G6: QUANTITE | H6: QUANTITE STOCK FINAL | J6: INVENTAIRE | K6: ECART | N6: QUANTITE | O6: QUANTITE STOCK FINAL | Q6: INVENTAIRE | R6: ECART
B8: BOUTEILLES CONSIGNES - PI
B9: JANVIER 2026 | K9: =IF(J9="","",J9-H9) | R9: =IF(Q9="","",Q9-O9)
B10: 46024 | C10: Entrée | E10: INVENTAIRE | H10: 1685 | J10: 1685 | K10: =IF(J10="","",J10-H10) -> 0 | O10: 35 | Q10: 35 | R10: =IF(Q10="","",Q10-O10) -> 0
B11: 46024 | C11: Sortie | E11: VENTE DE CONSIGNE | G11: 700 | H11: =IF(C11="","",IF(C11="Entrée",H10+G11,IF(C11="Sortie",H10-G11))) -> 985 | O11: =IF(C11="","",IF(C11="Entrée",O10+N11,IF(C11="Sortie",O10-N11))) -> 35
B12: 46025 | C12: Entrée | E12: INVENTAIRE | H12: =IF(C12="","",IF(C12="Entrée",H11+G12,IF(C12="Sortie",H11-G12))) -> 985 | K12: =IF(J12="","",J12-H12) | O12: 35 | Q12: 35 | R12: =IF(Q12="","",Q12-O12) -> 0
B13: 46025 | C13: Entrée | E13: APPRO CONSIGNE | G13: 700 | H13: =IF(C13="","",IF(C13="Entrée",H12+G13,IF(C13="Sortie",H12-G13))) -> 1685 | K13: =IF(J13="","",J13-H13) | O13: =IF(C13="","",IF(C13="Entrée",O12+N13,IF(C13="Sortie",O12-N13))) -> 35 | R13: =IF(Q13="","",Q13-O13)
B14: 46025 | C14: Entrée | E14: APPRO CONSIGNE | G14: 700 | H14: =IF(C14="","",IF(C14="Entrée",H13+G14,IF(C14="Sortie",H13-G14))) -> 2385 | K14: =IF(J14="","",J14-H14) | O14: =IF(C14="","",IF(C14="Entrée",O13+N14,IF(C14="Sortie",O13-N14))) -> 35 | R14: =IF(Q14="","",Q14-O14)
B15: 46025 | C15: Entrée | E15: APPRO CONSIGNE | G15: 700 | H15: =IF(C15="","",IF(C15="Entrée",H14+G15,IF(C15="Sortie",H14-G15))) -> 3085 | K15: =IF(J15="","",J15-H15) | O15: =IF(C15="","",IF(C15="Entrée",O14+N15,IF(C15="Sortie",O14-N15))) -> 35 | R15: =IF(Q15="","",Q15-O15)
B16: 46026 | C16: Entrée | E16: INVENTAIRE | H16: =IF(C16="","",IF(C16="Entrée",H15+G16,IF(C16="Sortie",H15-G16))) -> 3085 | J16: 3085 | K16: =IF(J16="","",J16-H16) -> 0 | O16: =IF(C16="","",IF(C16="Entrée",O15+N16,IF(C16="Sortie",O15-N16))) -> 35 | Q16: 35 | R16: =IF(Q16="","",Q16-O16) -> 0
B17: 46026 | C17: Sortie | E17: VENTE DE CONSIGNE | G17: 700 | H17: =IF(C17="","",IF(C17="Entrée",H16+G17,IF(C17="Sortie",H16-G17))) -> 2385 | K17: =IF(J17="","",J17-H17) | O17: =IF(C17="","",IF(C17="Entrée",O16+N17,IF(C17="Sortie",O16-N17))) -> 35 | R17: =IF(Q17="","",Q17-O17)
B18: 46027 | C18: Entrée | E18: INVENTAIRE | H18: =IF(C18="","",IF(C18="Entrée",H17+G18,IF(C18="Sortie",H17-G18))) -> 2385 | J18: =2318+67 -> 2385 | K18: =IF(J18="","",J18-H18) -> 0 | O18: =IF(C18="","",IF(C18="Entrée",O17+N18,IF(C18="Sortie",O17-N18))) -> 35 | Q18: 35 | R18: =IF(Q18="","",Q18-O18) -> 0
H19: =IF(C19="","",IF(C19="Entrée",H18+G19,IF(C19="Sortie",H18-G19))) | K19: =IF(J19="","",J19-H19) | O19: =IF(C19="","",IF(C19="Entrée",O18+N19,IF(C19="Sortie",O18-N19))) | R19: =IF(Q19="","",Q19-O19)
H20: =IF(C20="","",IF(C20="Entrée",H19+G20,IF(C20="Sortie",H19-G20))) | K20: =IF(J20="","",J20-H20) | O20: =IF(C20="","",IF(C20="Entrée",O19+N20,IF(C20="Sortie",O19-N20))) | R20: =IF(Q20="","",Q20-O20)
H21: =IF(C21="","",IF(C21="Entrée",H20+G21,IF(C21="Sortie",H20-G21))) | K21: =IF(J21="","",J21-H21) | O21: =IF(C21="","",IF(C21="Entrée",O20+N21,IF(C21="Sortie",O20-N21))) | R21: =IF(Q21="","",Q21-O21)
H22: =IF(C22="","",IF(C22="Entrée",#REF!+G22,IF(C22="Sortie",#REF!-G22))) | K22: =IF(J22="","",J22-H22)
F24: Cumul Entrée PI : | G24: =SUMIF(C9:C22,"Entrée",G9:G22) -> 2100 | Q24: Cumul Entrée B12 PI : | R24: =SUMIF(C9:C22,"Entrée",N9:N22) -> 0
F25: Cumul Sortie PI : | G25: =SUMIF(C9:C22,"Sortie",G9:G22) -> 1400 | Q25: Cumul Sortie B12 PI : | R25: =SUMIF(C9:C22,"Sortie",N9:N22) -> 0
G29: B6 | J29: INVENTAIRE | N29: B12 | Q29: INVENTAIRE
B30: DATE | C30: TYPE DE MVT | D30: Bon | E30: OPERATIONS | F30: PROVENANCE / DESTINATION | G30: QUANTITE | H30: QUANTITE STOCK FINAL | J30: INVENTAIRE | K30: ECART | N30: QUANTITE | O30: QUANTITE STOCK FINAL | Q30: INVENTAIRE | R30: ECART
B32: BOUTEILLES CONSIGNES - TEMCI | E32: OPERATION
B33: JANVIER 2026 | K33: =IF(J33="","",J33-H33) | R33: =IF(Q33="","",Q33-O33)
B34: 46024 | C34: Entrée | E34: INVENTAIRE | H34: 1260 | J34: 1260 | K34: =IF(J34="","",J34-H34) -> 0 | O34: 315 | Q34: 315 | R34: =IF(Q34="","",Q34-O34) -> 0
B35: 46024 | C35: Sortie | E35: VENTE DE CONSIGNE | H35: 1260 | O35: 315
B36: 46025 | C36: Entrée | E36: INVENTAIRE | H36: 1260 | K36: =IF(J36="","",J36-H36) | O36: 315 | R36: =IF(Q36="","",Q36-O36)
B37: 46025 | C37: Sortie | E37: VENTE DE CONSIGNE | G37: 105 | H37: =IF(C37="","",IF(C37="Entrée",H36+G37,IF(C37="Sortie",H36-G37))) -> 1155 | K37: =IF(J37="","",J37-H37) | O37: 315 | R37: =IF(Q37="","",Q37-O37)
B38: 46026 | C38: Entrée | E38: INVENTAIRE | H38: =IF(C38="","",IF(C38="Entrée",H37+G38,IF(C38="Sortie",H37-G38))) -> 1155 | J38: 1155 | K38: =IF(J38="","",J38-H38) -> 0 | O38: =IF(C38="","",IF(C38="Entrée",O37+N38,IF(C38="Sortie",O37-N38))) -> 315 | Q38: 315 | R38: =IF(Q38="","",Q38-O38) -> 0
B39: 46027 | C39: Entrée | E39: INVENTAIRE | H39: =IF(C39="","",IF(C39="Entrée",H38+G39,IF(C39="Sortie",H38-G39))) -> 1155 | J39: 1155 | K39: =IF(J39="","",J39-H39) -> 0 | O39: =IF(C39="","",IF(C39="Entrée",O38+N39,IF(C39="Sortie",O38-N39))) -> 315 | Q39: 315 | R39: =IF(Q39="","",Q39-O39) -> 0
H40: =IF(C40="","",IF(C40="Entrée",H39+G40,IF(C40="Sortie",H39-G40))) | K40: =IF(J40="","",J40-H40) | O40: =IF(C40="","",IF(C40="Entrée",O39+N40,IF(C40="Sortie",O39-N40))) | R40: =IF(Q40="","",Q40-O40)
H41: =IF(C41="","",IF(C41="Entrée",#REF!+G41,IF(C41="Sortie",#REF!-G41))) | K41: =IF(J41="","",J41-H41) | O41: =IF(C41="","",IF(C41="Entrée",#REF!+N41,IF(C41="Sortie",#REF!-N41))) | R41: =IF(Q41="","",Q41-O41)
K42: =IF(J42="","",J42-H42) | O42: =IF(C42="","",IF(C42="Entrée",O41+N42,IF(C42="Sortie",O41-N42))) | R42: =IF(Q42="","",Q42-O42)
H43: =IF(C43="","",IF(C43="Entrée",#REF!+G43,IF(C43="Sortie",#REF!-G43))) | K43: =IF(J43="","",J43-H43) | O43: =IF(C43="","",IF(C43="Entrée",#REF!+N43,IF(C43="Sortie",#REF!-N43))) | R43: =IF(Q43="","",Q43-O43)
H44: =IF(C44="","",IF(C44="Entrée",H43+G44,IF(C44="Sortie",H43-G44))) | K44: =IF(J44="","",J44-H44) | O44: =IF(C44="","",IF(C44="Entrée",O43+N44,IF(C44="Sortie",O43-N44))) | R44: =IF(Q44="","",Q44-O44)
F46: Cumul Entrée B6 TEMCI : | G46: =SUMIF(C33:C44,"Entrée",G33:G44) -> 0 | Q46: Cumul Entrée B12 TEMCI : | R46: =SUMIF(C33:C44,"Entrée",N33:N44) -> 0
F47: Cumul Sortie B6 TEMCI : | G47: =SUMIF(C33:C44,"Sortie",G33:G44) -> 105 | Q47: Cumul Sortie B12 TEMCI : | R47: =SUMIF(C33:C44,"Sortie",N33:N44) -> 0

Sheet PARC BOUTEILLES CE (PI & TEMCI)
B1: SAEPP | K1: Année: 2025 | R1: Menu
B3: FICHE DE SUIVI DE STOCKS | G3: STOCK OUTILS CE | Q3: MOIS : | R3: =TEXT(TODAY(),"mmmm") -> janvier
B5: BOUTEILLES PI | G5: B6 | J5: INVENTAIRE | N5: B12 | Q5: INVENTAIRE
B6: DATE | C6: TYPE DE MVT | D6: Bon | E6: OPERATIONS | F6: DESTINATION / PROVENANCE | G6: QUANTITE | H6: QUANTITE STOCK FINAL | J6: INVENTAIRE | K6: ECART | N6: QUANTITE | O6: QUANTITE STOCK FINAL | Q6: INVENTAIRE | R6: ECART
B8: STOCK OUTILS
B9: JANVIER 2026 | K9: =IF(J9="","",J9-H9) | R9: =IF(Q9="","",Q9-O9)
B10: 46024 | E10: INVENTAIRE | H10: 10965 | J10: 10965 | K10: =IF(J10="","",J10-H10) -> 0 | O10: 5267 | Q10: 5267 | R10: =IF(Q10="","",Q10-O10) -> 0
B11: 46025 | C11: Entrée | E11: INVENTAIRE | H11: =IF(C11="","",IF(C11="Entrée",H10+G11,IF(C11="Sortie",H10-G11))) -> 10965 | J11: =6973+199+700+271+124+754+1131+812+1 -> 10965 | K11: =IF(J11="","",J11-H11) -> 0 | O11: =IF(C11="","",IF(C11="Entrée",O10+N11,IF(C11="Sortie",O10-N11))) -> 5267 | Q11: =10+10+8+3+17+87+16+22+428+3301+1365 -> 5267 | R11: =IF(Q11="","",Q11-O11) -> 0
B12: 46025 | C12: Sortie | D12: 110 | E12: SORTIE HS | G12: 770 | H12: =IF(C12="","",IF(C12="Entrée",H11+G12,IF(C12="Sortie",H11-G12))) -> 10195 | K12: =IF(J12="","",J12-H12) | N12: 70 | O12: =IF(C12="","",IF(C12="Entrée",O11+N12,IF(C12="Sortie",O11-N12))) -> 5197 | R12: =IF(Q12="","",Q12-O12)
B13: 46026 | C13: Entrée | E13: INVENTAIRE | H13: =IF(C13="","",IF(C13="Entrée",H12+G13,IF(C13="Sortie",H12-G13))) -> 10195 | J13: 10195 | K13: =IF(J13="","",J13-H13) -> 0 | O13: =IF(C13="","",IF(C13="Entrée",O12+N13,IF(C13="Sortie",O12-N13))) -> 5197 | Q13: 5197 | R13: =IF(Q13="","",Q13-O13) -> 0
B14: 46027 | C14: Entrée | E14: INVENTAIRE | H14: =IF(C14="","",IF(C14="Entrée",H13+G14,IF(C14="Sortie",H13-G14))) -> 10195 | J14: =8498+1696+1 -> 10195 | K14: =IF(J14="","",J14-H14) -> 0 | O14: =IF(C14="","",IF(C14="Entrée",O13+N14,IF(C14="Sortie",O13-N14))) -> 5197 | Q14: =80+5101+16 -> 5197 | R14: =IF(Q14="","",Q14-O14) -> 0
H15: =IF(C15="","",IF(C15="Entrée",H14+G15,IF(C15="Sortie",H14-G15))) | K15: =IF(J15="","",J15-H15) | O15: =IF(C15="","",IF(C15="Entrée",O14+N15,IF(C15="Sortie",O14-N15))) | R15: =IF(Q15="","",Q15-O15)
H16: =IF(C16="","",IF(C16="Entrée",H15+G16,IF(C16="Sortie",H15-G16))) | K16: =IF(J16="","",J16-H16) | O16: =IF(C16="","",IF(C16="Entrée",O15+N16,IF(C16="Sortie",O15-N16))) | R16: =IF(Q16="","",Q16-O16)
H17: =IF(C17="","",IF(C17="Entrée",H16+G17,IF(C17="Sortie",H16-G17))) | K17: =IF(J17="","",J17-H17) | O17: =IF(C17="","",IF(C17="Entrée",O16+N17,IF(C17="Sortie",O16-N17))) | R17: =IF(Q17="","",Q17-O17)
H18: =IF(C18="","",IF(C18="Entrée",H17+G18,IF(C18="Sortie",H17-G18))) | K18: =IF(J18="","",J18-H18) | O18: =IF(C18="","",IF(C18="Entrée",O17+N18,IF(C18="Sortie",O17-N18))) | R18: =IF(Q18="","",Q18-O18)
H19: =IF(C19="","",IF(C19="Entrée",H18+G19,IF(C19="Sortie",H18-G19))) | K19: =IF(J19="","",J19-H19) | O19: =IF(C19="","",IF(C19="Entrée",O18+N19,IF(C19="Sortie",O18-N19))) | R19: =IF(Q19="","",Q19-O19)
H20: =IF(C20="","",IF(C20="Entrée",H19+G20,IF(C20="Sortie",H19-G20))) | K20: =IF(J20="","",J20-H20) | O20: =IF(C20="","",IF(C20="Entrée",O19+N20,IF(C20="Sortie",O19-N20))) | R20: =IF(Q20="","",Q20-O20)
H21: =IF(C21="","",IF(C21="Entrée",H20+G21,IF(C21="Sortie",H20-G21))) | K21: =IF(J21="","",J21-H21) | O21: =IF(C21="","",IF(C21="Entrée",O20+N21,IF(C21="Sortie",O20-N21))) | R21: =IF(Q21="","",Q21-O21)
H22: =IF(C22="","",IF(C22="Entrée",H21+G22,IF(C22="Sortie",H21-G22))) | K22: =IF(J22="","",J22-H22) | O22: =IF(C22="","",IF(C22="Entrée",O21+N22,IF(C22="Sortie",O21-N22))) | R22: =IF(Q22="","",Q22-O22)
H23: =IF(C23="","",IF(C23="Entrée",#REF!+G23,IF(C23="Sortie",#REF!-G23))) | K23: =IF(J23="","",J23-H23) | O23: =IF(C23="","",IF(C23="Entrée",#REF!+N23,IF(C23="Sortie",#REF!-N23))) | R23: =IF(Q23="","",Q23-O23)
F25: Cumul Entrée PI : | G25: =SUMIF(C9:C23,"Entrée",G9:G23) -> 0 | Q25: Cumul Entrée B12 PI : | R25: =SUMIF(C9:C23,"Entrée",N9:N23) -> 0
F26: Cumul Sortie PI : | G26: =SUMIF(C9:C23,"Sortie",G9:G23) -> 770 | Q26: Cumul Sortie B12 PI : | R26: =SUMIF(C9:C23,"Sortie",N9:N23) -> 70
B30: BOUTEILLES TEMCI | G30: B6 | J30: INVENTAIRE | N30: B12 | Q30: INVENTAIRE
B31: DATE | C31: TYPE DE MVT | D31: Bon | E31: OPERATIONS | F31: PROVENANCE / DESTINATION | G31: QUANTITE | H31: QUANTITE STOCK FINAL | J31: INVENTAIRE | K31: ECART | N31: QUANTITE | O31: QUANTITE STOCK FINAL | Q31: INVENTAIRE | R31: ECART
B33: STOCK OUTILS
B34: JANVIER 2026 | K34: =IF(J34="","",J34-H34) | R34: =IF(Q34="","",Q34-O34)
B35: 46024 | E35: INVENTAIRE | H35: 9759 | J35: 9759 | K35: =IF(J35="","",J35-H35) -> 0 | O35: 2111 | Q35: 2111 | R35: =IF(Q35="","",Q35-O35) -> 0
B36: 46025 | C36: Entrée | E36: INVENTAIRE | H36: =IF(C36="","",IF(C36="Entrée",H35+G36,IF(C36="Sortie",H35-G36))) -> 9759 | J36: =6119+95+2868+30+145+46+188+266+2 -> 9759 | K36: =IF(J36="","",J36-H36) -> 0 | O36: =IF(C36="","",IF(C36="Entrée",O35+N36,IF(C36="Sortie",O35-N36))) -> 2111 | Q36: =50+17+2+240+14+18+24+5+526+24+1191 -> 2111 | R36: =IF(Q36="","",Q36-O36) -> 0
B37: 46025 | C37: Sortie | D37: 111 | E37: SORTIE HS | G37: 266 | H37: =IF(C37="","",IF(C37="Entrée",H36+G37,IF(C37="Sortie",H36-G37))) -> 9493 | K37: =IF(J37="","",J37-H37) | N37: 252 | O37: =IF(C37="","",IF(C37="Entrée",O36+N37,IF(C37="Sortie",O36-N37))) -> 1859 | R37: =IF(Q37="","",Q37-O37)
B38: 46026 | C38: Entrée | E38: INVENTAIRE | H38: =IF(C38="","",IF(C38="Entrée",H37+G38,IF(C38="Sortie",H37-G38))) -> 9493 | J38: 9493 | K38: =IF(J38="","",J38-H38) -> 0 | O38: =IF(C38="","",IF(C38="Entrée",O37+N38,IF(C38="Sortie",O37-N38))) -> 1859 | Q38: 1859 | R38: =IF(Q38="","",Q38-O38) -> 0
B39: 46027 | C39: Entrée | E39: INVENTAIRE | H39: =IF(C39="","",IF(C39="Entrée",H38+G39,IF(C39="Sortie",H38-G39))) -> 9493 | J39: =9194+151+99+21+26+2 -> 9493 | K39: =IF(J39="","",J39-H39) -> 0 | O39: =IF(C39="","",IF(C39="Entrée",O38+N39,IF(C39="Sortie",O38-N39))) -> 1859 | Q39: =128+1731 -> 1859 | R39: =IF(Q39="","",Q39-O39) -> 0
H40: =IF(C40="","",IF(C40="Entrée",H39+G40,IF(C40="Sortie",H39-G40))) | K40: =IF(J40="","",J40-H40) | O40: =IF(C40="","",IF(C40="Entrée",#REF!+N40,IF(C40="Sortie",#REF!-N40))) | R40: =IF(Q40="","",Q40-O40)
H41: =IF(C41="","",IF(C41="Entrée",H40+G41,IF(C41="Sortie",H40-G41))) | K41: =IF(J41="","",J41-H41) | O41: =IF(C41="","",IF(C41="Entrée",O40+N41,IF(C41="Sortie",O40-N41))) | R41: =IF(Q41="","",Q41-O41)
H42: =IF(C42="","",IF(C42="Entrée",H41+G42,IF(C42="Sortie",H41-G42))) | K42: =IF(J42="","",J42-H42) | O42: =IF(C42="","",IF(C42="Entrée",O41+N42,IF(C42="Sortie",O41-N42))) | R42: =IF(Q42="","",Q42-O42)
H43: =IF(C43="","",IF(C43="Entrée",H42+G43,IF(C43="Sortie",H42-G43))) | K43: =IF(J43="","",J43-H43) | O43: =IF(C43="","",IF(C43="Entrée",O42+N43,IF(C43="Sortie",O42-N43))) | R43: =IF(Q43="","",Q43-O43)
H44: =IF(C44="","",IF(C44="Entrée",H43+G44,IF(C44="Sortie",H43-G44))) | K44: =IF(J44="","",J44-H44) | O44: =IF(C44="","",IF(C44="Entrée",O43+N44,IF(C44="Sortie",O43-N44))) | R44: =IF(Q44="","",Q44-O44)
H45: =IF(C45="","",IF(C45="Entrée",H44+G45,IF(C45="Sortie",H44-G45))) | K45: =IF(J45="","",J45-H45) | R45: =IF(Q45="","",Q45-O45)
H46: =IF(C46="","",IF(C46="Entrée",H45+G46,IF(C46="Sortie",H45-G46))) | K46: =IF(J46="","",J46-H46) | R46: =IF(Q46="","",Q46-O46)
H47: =IF(C47="","",IF(C47="Entrée",H46+G47,IF(C47="Sortie",H46-G47))) | K47: =IF(J47="","",J47-H47) | R47: =IF(Q47="","",Q47-O47)
H48: =IF(C48="","",IF(C48="Entrée",H47+G48,IF(C48="Sortie",H47-G48))) | K48: =IF(J48="","",J48-H48) | R48: =IF(Q48="","",Q48-O48)
...

Sheet Synthèses Stocks (2)
B1: SAEPP | T1: Menu
S2: Année: | T2: 2025
B3: FICHE DE SUIVI DE STOCKS | E3: SYNTHESES - ETATS DE STOCKS AU 14/07/2025 | S3: MOIS : | T3: JUILLET
B5: BOUTEILLES PI | G5: B6 | J5: INVENTAIRE | O5: B12 | S5: INVENTAIRE
B6: DATE | C6: TYPES DE STOCKS | D6: DESTINATION / PROVENANCE | E6: QUANTITE STOCK INITIAL | F6: ENTREE EN STOCKS | G6: SORTIE DE STOCKS | H6: QUANTITE STOCK FINAL | J6: INVENTAIRE | K6: ECART | N6: QUANTITE STOCK INITIAL | O6: ENTREE EN STOCKS | P6: SORTIE DE STOCKS | Q6: QUANTITE STOCK FINAL | S6: INVENTAIRE | T6: ECART | V6: JUSTIFICATIF D'ÉCART
K8: =IF(J8="","",J8-H8) | T8: =IF(S8="","",S8-Q8)
B9: 45839 | C9: BOUTEILLES NEUVES | E9: 0 | H9: =+E9+F9-G9 -> 0 | J9: 0 | K9: =IF(J9="","",J9-H9) -> 0 | N9: 0 | O9: =+'Btles Neuve _ DV'!R22 -> 0 | P9: =+'Btles Neuve _ DV'!R23 -> 0 | Q9: =+N9+O9-P9 -> 0 | S9: 0 | T9: =IF(S9="","",S9-Q9) -> 0
C10: BOUTEILLES CONSIGNES | E10: 1639 | H10: =+E10+F10-G10 -> 1639 | J10: 2339 | K10: =IF(J10="","",J10-H10) -> 700 | N10: ='Consigne _ CE'!Q10 -> 35 | O10: ='Consigne _ CE'!R24 -> 0 | P10: ='Consigne _ CE'!R25 -> 0 | Q10: =+N10+O10-P10 -> 35 | S10: 353 | T10: =IF(S10="","",S10-Q10) -> 318
C11: BOUTEILLES STOCK OUTIL | E11: 16083 | H11: =+E11+F11-G11 -> 16083 | J11: 15945 | K11: =IF(J11="","",J11-H11) -> -138 | N11: ='PARC BOUTEILLES CE (PI & TEMCI)'!Q10 -> 5267 | O11: ='PARC BOUTEILLES CE (PI & TEMCI)'!R25 -> 0 | P11: ='PARC BOUTEILLES CE (PI & TEMCI)'!R26 -> 70 | Q11: =+N11+O11-P11 -> 5197 | S11: 3992 | T11: =IF(S11="","",S11-Q11) -> -1205
C12: BOUTEILLES HS | E12: ='Btles HS _ DV'!J10 -> 16301 | F12: ='Btles HS _ DV'!G23 -> 770 | G12: ='Btles HS _ DV'!G24 -> 0 | H12: =+E12+F12-G12 -> 17071 | J12: 5205 | K12: =IF(J12="","",J12-H12) -> -11866 | N12: ='Btles HS _ DV'!Q10 -> 1128 | O12: ='Btles HS _ DV'!R23 -> 70 | P12: ='Btles HS _ DV'!R24 -> 0 | Q12: =+N12+O12-P12 -> 1198 | S12: 315 | T12: =IF(S12="","",S12-Q12) -> -883
C13: BOUTEILLES TDS | E13: ='PEINTURE TDS '!J10 -> 0 | F13: ='PEINTURE TDS '!G23 -> 0 | G13: ='PEINTURE TDS '!G24 -> 0 | H13: =+E13+F13-G13 -> 0 | K13: =IF(J13="","",J13-H13) | N13: ='PEINTURE TDS '!Q10 -> 0 | O13: ='PEINTURE TDS '!R23 -> 0 | P13: ='PEINTURE TDS '!R24 -> 0 | Q13: =+N13+O13-P13 -> 0 | T13: =IF(S13="","",S13-Q13)
T14: =IF(S14="","",S14-Q14)
K15: =IF(J15="","",J15-H15) | T15: =IF(S15="","",S15-Q15)
G17: TOTAL | H17: =+SUM(H8:H15) -> 34793 | K17: =+SUM(K8:K15) -> -11304 | Q17: =+SUM(Q8:Q15) -> 6430 | R17: =+SUM(R8:R15) -> 0 | T17: =+SUM(T8:T15) -> -1770
B20: BOUTEILLES TEMCI | G20: B6 | J20: INVENTAIRE | O20: B12 | S20: INVENTAIRE
B21: DATE | C21: TYPES DE STOCKS | D21: DESTINATION / PROVENANCE | E21: QUANTITE STOCK INITIAL | F21: ENTREE EN STOCKS | G21: SORTIE DE STOCKS | H21: QUANTITE STOCK FINAL | J21: INVENTAIRE | K21: ECART | N21: QUANTITE STOCK INITIAL | O21: ENTREE EN STOCKS | P21: SORTIE DE STOCKS | Q21: QUANTITE STOCK FINAL | S21: INVENTAIRE | T21: ECART | V21: JUSTIFICATIF D'ÉCART
K23: =IF(J23="","",J23-H23) | T23: =IF(S23="","",S23-Q23)
B24: 45839 | C24: BOUTEILLES NEUVES | E24: =+'Btles Neuve _ DV'!J32 -> 24687 | F24: =+'Btles Neuve _ DV'!G42 -> 0 | G24: =+'Btles Neuve _ DV'!G43 -> 0 | H24: =+E24+F24-G24 -> 24687 | J24: 23671 | K24: =IF(J24="","",J24-H24) -> -1016 | N24: =+'Btles Neuve _ DV'!Q32 -> 2161 | O24: =+'Btles Neuve _ DV'!R42 -> 0 | P24: =+'Btles Neuve _ DV'!R43 -> 0 | Q24: =+N24+O24-P24 -> 2161 | S24: 505 | T24: =IF(S24="","",S24-Q24) -> -1656
C25: BOUTEILLES CONSIGNES | E25: ='Consigne _ CE'!J34 -> 1260 | F25: ='Consigne _ CE'!G46 -> 0 | G25: ='Consigne _ CE'!G47 -> 105 | H25: =+E25+F25-G25 -> 1155 | J25: 910 | K25: =IF(J25="","",J25-H25) -> -245 | N25: ='Consigne _ CE'!Q34 -> 315 | O25: ='Consigne _ CE'!R46 -> 0 | P25: ='Consigne _ CE'!R47 -> 0 | Q25: =+N25+O25-P25 -> 315 | S25: 210 | T25: =IF(S25="","",S25-Q25) -> -105
C26: BOUTEILLES STOCK OUTIL | E26: ='PARC BOUTEILLES CE (PI & TEMCI)'!J35 -> 9759 | F26: ='PARC BOUTEILLES CE (PI & TEMCI)'!G52 -> 0 | G26: ='PARC BOUTEILLES CE (PI & TEMCI)'!G53 -> 266 | H26: =+E26+F26-G26 -> 9493 | J26: 14108 | K26: =IF(J26="","",J26-H26) -> 4615 | N26: ='PARC BOUTEILLES CE (PI & TEMCI)'!Q35 -> 2111 | O26: ='PARC BOUTEILLES CE (PI & TEMCI)'!R52 -> 0 | P26: ='PARC BOUTEILLES CE (PI & TEMCI)'!R53 -> 252 | Q26: =+N26+O26-P26 -> 1859 | S26: 5538 | T26: =IF(S26="","",S26-Q26) -> 3679
C27: BOUTEILLES HS | E27: ='Btles HS _ DV'!J33 -> 1708 | F27: ='Btles HS _ DV'!G44 -> 266 | G27: ='Btles HS _ DV'!G45 -> 0 | H27: =+E27+F27-G27 -> 1974 | J27: 894 | K27: =IF(J27="","",J27-H27) -> -1080 | N27: ='Btles HS _ DV'!Q33 -> 925 | O27: ='Btles HS _ DV'!R44 -> 252 | P27: ='Btles HS _ DV'!R45 -> 0 | Q27: =+N27+O27-P27 -> 1177 | S27: 389 | T27: =IF(S27="","",S27-Q27) -> -788
C28: BOUTEILLES TDS | E28: ='PEINTURE TDS '!J33 -> 0 | F28: ='PEINTURE TDS '!G47 -> 0 | G28: ='PEINTURE TDS '!G48 -> 0 | H28: =+E28+F28-G28 -> 0 | K28: =IF(J28="","",J28-H28) | N28: ='PEINTURE TDS '!Q33 -> 0 | O28: ='PEINTURE TDS '!R47 -> 0 | P28: ='PEINTURE TDS '!R48 -> 0 | Q28: =+N28+O28-P28 -> 0 | T28: =IF(S28="","",S28-Q28)
K29: =IF(J29="","",J29-H29) | T29: =IF(S29="","",S29-Q29)
K30: =IF(J30="","",J30-H30) | T30: =IF(S30="","",S30-Q30)
G32: TOTAL | H32: =+SUM(H23:H30) -> 37309 | K32: =+SUM(K23:K30) -> 2274 | Q32: =+SUM(Q23:Q30) -> 5512 | R32: =+SUM(R23:R30) -> 0 | T32: =+SUM(T23:T30) -> 1130
B35: BOUTEILLES VIVO ENERGY | G35: B6 | J35: INVENTAIRE | O35: B12 | S35: INVENTAIRE
B36: DATE | C36: TYPES DE STOCKS | D36: DESTINATION / PROVENANCE | E36: QUANTITE STOCK INITIAL | F36: ENTREE EN STOCKS | G36: SORTIE DE STOCKS | H36: QUANTITE STOCK FINAL | J36: INVENTAIRE | K36: ECART | N36: QUANTITE STOCK INITIAL | O36: ENTREE EN STOCKS | P36: SORTIE DE STOCKS | Q36: QUANTITE STOCK FINAL | S36: INVENTAIRE | T36: ECART | V36: JUSTIFICATIF D'ÉCART
K38: =IF(J38="","",J38-H38) | T38: =IF(S38="","",S38-Q38)
B39: 45839 | C39: BOUTEILLES NEUVES | E39: =+'Btles Neuve _ DV'!J51 -> 0 | F39: ='Btles Neuve _ DV'!G62 -> 0 | G39: ='Btles Neuve _ DV'!G63 -> 0 | H39: =+E39+F39-G39 -> 0 | J39: 750 | K39: =IF(J39="","",J39-H39) -> 750 | Q39: =+N39+O39-P39 -> 0 | T39: =IF(S39="","",S39-Q39)
C40: BOUTEILLES CONSIGNES | H40: =+E40+F40-G40 -> 0 | K40: =IF(J40="","",J40-H40) | Q40: =+N40+O40-P40 -> 0 | T40: =IF(S40="","",S40-Q40)
C41: BOUTEILLES STOCK OUTIL | E41: ='STOCK OUTILS VIVO'!J10 -> 1103 | F41: ='STOCK OUTILS VIVO'!G20 -> 0 | G41: ='STOCK OUTILS VIVO'!G21 -> 0 | H41: =+E41+F41-G41 -> 1103 | J41: 560 | K41: =IF(J41="","",J41-H41) -> -543 | N41: ='STOCK OUTILS VIVO'!Q10 -> 34 | O41: ='STOCK OUTILS VIVO'!R20 -> 0 | P41: ='STOCK OUTILS VIVO'!R21 -> 0 | Q41: =+N41+O41-P41 -> 34 | S41: 35 | T41: =IF(S41="","",S41-Q41) -> 1 | V41: 175 Bouteilles B6 sorties au shift de nuit sur le BT N°18926
C42: BOUTEILLES HS | H42: =+E42+F42-G42 -> 0 | K42: =IF(J42="","",J42-H42) | Q42: =+N42+O42-P42 -> 0 | T42: =IF(S42="","",S42-Q42) | V42: 280 Bouteilles B12 sorties au shift de nuit sur le BT N°18926
C43: BOUTEILLES TDS | H43: =+E43+F43-G43 -> 0 | K43: =IF(J43="","",J43-H43) | Q43: =+N43+O43-P43 -> 0 | T43: =IF(S43="","",S43-Q43) | V43: -1 Bouteille B12 Ecart non justifié
H44: =+E44+F44-G44 -> 0 | K44: =IF(J44="","",J44-H44) | Q44: =+N44+O44-P44 -> 0 | T44: =IF(S44="","",S44-Q44)
K45: =IF(J45="","",J45-H45) | T45: =IF(S45="","",S45-Q45)
G47: TOTAL | H47: =+SUM(H38:H45) -> 1103 | K47: =+SUM(K38:K45) -> 207 | Q47: =+SUM(Q38:Q45) -> 34 | R47: =+SUM(R38:R45) -> 0 | T47: =+SUM(T38:T45) -> 1

Sheet STOCK OUTILS VIVO
B1: SAEPP | K1: Année: 2025 | R1: Menu
B3: FICHE DE SUIVI DE STOCKS | G3: STOCK OUTILS VIVO ENERGY | Q3: MOIS : | R3: =TEXT(TODAY(),"mmmm") -> janvier
B5: BOUTEILLES VIVO ENERGY | G5: B6 | J5: INVENTAIRE | N5: B12 | Q5: INVENTAIRE
B6: DATE | C6: TYPE DE MVT | D6: Bon | E6: OPERATIONS | F6: DESTINATION / PROVENANCE | G6: QUANTITE | H6: QUANTITE STOCK FINAL | J6: INVENTAIRE | K6: ECART | N6: QUANTITE | O6: QUANTITE STOCK FINAL | Q6: INVENTAIRE | R6: ECART
B8: STOCK OUTILS
B9: JANVIER 2026 | K9: =IF(J9="","",J9-H9) | R9: =IF(Q9="","",Q9-O9)
B10: 46024 | C10: Entrée | E10: INVENTAIRE | H10: 1103 | J10: 1103 | K10: =IF(J10="","",J10-H10) -> 0 | O10: 34 | Q10: 34 | R10: =IF(Q10="","",Q10-O10) -> 0
B11: 46025 | C11: Entrée | E11: INVENTAIRE | H11: =IF(C11="","",IF(C11="Entrée",H10+G11,IF(C11="Sortie",H10-G11))) -> 1103 | J11: 1103 | K11: =IF(J11="","",J11-H11) -> 0 | O11: =IF(C11="","",IF(C11="Entrée",O10+N11,IF(C11="Sortie",O10-N11))) -> 34 | Q11: 34 | R11: =IF(Q11="","",Q11-O11) -> 0
B12: 46026 | C12: Entrée | E12: INVENTAIRE | H12: =IF(C12="","",IF(C12="Entrée",H11+G12,IF(C12="Sortie",H11-G12))) -> 1103 | J12: 1103 | K12: =IF(J12="","",J12-H12) -> 0 | O12: =IF(C12="","",IF(C12="Entrée",O11+N12,IF(C12="Sortie",O11-N12))) -> 34 | Q12: 34 | R12: =IF(Q12="","",Q12-O12) -> 0
B13: 46027 | C13: Entrée | E13: INVENTAIRE | H13: =IF(C13="","",IF(C13="Entrée",H12+G13,IF(C13="Sortie",H12-G13))) -> 1103 | J13: 1103 | K13: =IF(J13="","",J13-H13) -> 0 | O13: =IF(C13="","",IF(C13="Entrée",O12+N13,IF(C13="Sortie",O12-N13))) -> 34 | Q13: 34 | R13: =IF(Q13="","",Q13-O13) -> 0
H14: =IF(C14="","",IF(C14="Entrée",H13+G14,IF(C14="Sortie",H13-G14))) | K14: =IF(J14="","",J14-H14) | O14: =IF(C14="","",IF(C14="Entrée",O13+N14,IF(C14="Sortie",O13-N14))) | R14: =IF(Q14="","",Q14-O14)
H15: =IF(C15="","",IF(C15="Entrée",H14+G15,IF(C15="Sortie",H14-G15))) | K15: =IF(J15="","",J15-H15) | O15: =IF(C15="","",IF(C15="Entrée",O14+N15,IF(C15="Sortie",O14-N15))) | R15: =IF(Q15="","",Q15-O15)
H16: =IF(C16="","",IF(C16="Entrée",H15+G16,IF(C16="Sortie",H15-G16))) | K16: =IF(J16="","",J16-H16) | O16: =IF(C16="","",IF(C16="Entrée",O15+N16,IF(C16="Sortie",O15-N16))) | R16: =IF(Q16="","",Q16-O16)
H17: =IF(C17="","",IF(C17="Entrée",H16+G17,IF(C17="Sortie",H16-G17))) | K17: =IF(J17="","",J17-H17) | O17: =IF(C17="","",IF(C17="Entrée",O16+N17,IF(C17="Sortie",O16-N17))) | R17: =IF(Q17="","",Q17-O17)
H18: =IF(C18="","",IF(C18="Entrée",#REF!+G18,IF(C18="Sortie",#REF!-G18))) | K18: =IF(J18="","",J18-H18) | O18: =IF(C18="","",IF(J18="Entrée",#REF!+N18,IF(J18="Sortie",#REF!-N18))) | R18: =IF(Q18="","",Q18-O18)
F20: Cumul Entrée PI : | G20: =SUMIF(C9:C18,"Entrée",G9:G18) -> 0 | Q20: Cumul Entrée B12 PI : | R20: =SUMIF(C9:C18,"Entrée",N9:N18) -> 0
F21: Cumul Sortie PI : | G21: =SUMIF(C9:C18,"Sortie",G9:G18) -> 0 | Q21: Cumul Sortie B12 PI : | R21: =SUMIF(C9:C18,"Sortie",N9:N18) -> 0

Sheet PEINTURE TDS 
B1: SAEPP | K1: Année: 2025 | R1: Menu
B3: FICHE DE SUIVI DE STOCKS | G3: BOUTEILLES A LA PEINTURE
G5: B6 | J5: INVENTAIRE | N5: B12 | Q5: INVENTAIRE
B6: DATE | C6: TYPE DE MVT | D6: Bon | E6: OPERATIONS | F6: DESTINATION / PROVENANCE | G6: QUANTITE | H6: QUANTITE STOCK FINAL | J6: INVENTAIRE | K6: ECART | N6: QUANTITE | O6: QUANTITE STOCK FINAL | Q6: INVENTAIRE | R6: ECART
B8: BOUTEILLES A LA PEINTURE PI
B9: OCTOBRE 2025 | K9: =IF(J9="","",J9-H9) | R9: =IF(Q9="","",Q9-O9)
B10: 45931 | E10: INVENTAIRE | H10: =G10 -> 0 | K10: =IF(J10="","",J10-H10) | O10: =N10 -> 0 | R10: =IF(Q10="","",Q10-O10)
H11: =IF(C11="","",IF(C11="Entrée",H10+G11,IF(C11="Sortie",H10-G11))) | K11: =IF(J11="","",J11-H11) | R11: =IF(Q11="","",Q11-O11)
H12: =IF(C12="","",IF(C12="Entrée",H11+G12,IF(C12="Sortie",H11-G12))) | K12: =IF(J12="","",J12-H12) | R12: =IF(Q12="","",Q12-O12)
H13: =IF(C13="","",IF(C13="Entrée",H12+G13,IF(C13="Sortie",H12-G13))) | K13: =IF(J13="","",J13-H13) | R13: =IF(Q13="","",Q13-O13)
H14: =IF(C14="","",IF(C14="Entrée",H13+G14,IF(C14="Sortie",H13-G14))) | K14: =IF(J14="","",J14-H14) | R14: =IF(Q14="","",Q14-O14)
H15: =IF(C15="","",IF(C15="Entrée",H14+G15,IF(C15="Sortie",H14-G15))) | K15: =IF(J15="","",J15-H15) | R15: =IF(Q15="","",Q15-O15)
H16: =IF(C16="","",IF(C16="Entrée",H15+G16,IF(C16="Sortie",H15-G16))) | K16: =IF(J16="","",J16-H16) | R16: =IF(Q16="","",Q16-O16)
H17: =IF(C17="","",IF(C17="Entrée",H16+G17,IF(C17="Sortie",H16-G17))) | K17: =IF(J17="","",J17-H17) | R17: =IF(Q17="","",Q17-O17)
H18: =IF(C18="","",IF(C18="Entrée",H17+G18,IF(C18="Sortie",H17-G18))) | K18: =IF(J18="","",J18-H18) | O18: =IF(C18="","",IF(C18="Entrée",#REF!+N18,IF(C18="Sortie",#REF!-N18))) | R18: =IF(Q18="","",Q18-O18)
H19: =IF(C19="","",IF(C19="Entrée",H18+G19,IF(C19="Sortie",H18-G19))) | K19: =IF(J19="","",J19-H19) | R19: =IF(Q19="","",Q19-O19)
H20: =IF(C20="","",IF(C20="Entrée",#REF!+G20,IF(C20="Sortie",#REF!-G20))) | K20: =IF(J20="","",J20-H20) | R20: =IF(Q20="","",Q20-O20)
H21: =IF(C21="","",IF(C21="Entrée",#REF!+G21,IF(C21="Sortie",#REF!-G21))) | K21: =IF(J21="","",J21-H21) | O21: =IF(C21="","",IF(J21="Entrée",#REF!+N21,IF(J21="Sortie",#REF!-N21))) | R21: =IF(Q21="","",Q21-O21)
F23: Cumul Entrée PI : | G23: =SUMIF(C11:C21,"Entrée",G10:G21) -> 0 | Q23: Cumul Entrée B12 PI : | R23: =SUMIF(C11:C21,"Entrée",N10:N21) -> 0
F24: Cumul Sortie PI : | G24: =SUMIF(C9:C21,"Sortie",G9:G21) -> 0 | Q24: Cumul Sortie B12 PI : | R24: =SUMIF(C9:C21,"Sortie",N9:N21) -> 0
G28: B6 | J28: INVENTAIRE | N28: B12 | Q28: INVENTAIRE
B29: DATE | C29: TYPE DE MVT | D29: Bon | E29: OPERATIONS | F29: PROVENANCE / DESTINATION | G29: QUANTITE | H29: QUANTITE STOCK FINAL | J29: INVENTAIRE | K29: ECART | N29: QUANTITE | O29: QUANTITE STOCK FINAL | Q29: INVENTAIRE | R29: ECART
B31: BBOUTEILLES A LA PEINTURE - TEMCI
B32: OCTOBRE 2025 | K32: =IF(J32="","",J32-H32) | R32: =IF(Q32="","",Q32-O32)
B33: 45931 | H33: =G33 -> 0 | K33: =IF(J33="","",J33-H33) | O33: =N33 -> 0 | R33: =IF(Q33="","",Q33-O33)
K34: =IF(J34="","",J34-H34) | O34: =N34 -> 0 | R34: =IF(Q34="","",Q34-O34)
K35: =IF(J35="","",J35-H35) | O35: =N35 -> 0 | R35: =IF(Q35="","",Q35-O35)
K36: =IF(J36="","",J36-H36) | O36: =N36 -> 0 | R36: =IF(Q36="","",Q36-O36)
K37: =IF(J37="","",J37-H37) | O37: =N37 -> 0 | R37: =IF(Q37="","",Q37-O37)
K38: =IF(J38="","",J38-H38) | O38: =N38 -> 0 | R38: =IF(Q38="","",Q38-O38)
K39: =IF(J39="","",J39-H39) | O39: =N39 -> 0 | R39: =IF(Q39="","",Q39-O39)
K40: =IF(J40="","",J40-H40) | O40: =N40 -> 0 | R40: =IF(Q40="","",Q40-O40)
K41: =IF(J41="","",J41-H41) | O41: =N41 -> 0 | R41: =IF(Q41="","",Q41-O41)
K42: =IF(J42="","",J42-H42) | R42: =IF(Q42="","",Q42-O42)
K43: =IF(J43="","",J43-H43) | R43: =IF(Q43="","",Q43-O43)
K44: =IF(J44="","",J44-H44)
H45: =IF(C45="","",IF(C45="Entrée",H37+G45,IF(C45="Sortie",H37-G45))) | K45: =IF(J45="","",J45-H45) | O45: =IF(C45="","",IF(C45="Entrée",O37+N45,IF(C45="Sortie",O37-N45))) | R45: =IF(Q45="","",Q45-O45)
F47: Cumul Entrée B6 TEMCI : | G47: =SUMIF(C33:C45,"Entrée",G33:G45) -> 0 | Q47: Cumul Entrée B12 TEMCI : | R47: =SUMIF(C33:C45,"Entrée",N33:N45) -> 0
F48: Cumul Sortie B6 TEMCI : | G48: =SUMIF(C32:C45,"Sortie",G32:G45) -> 0 | Q48: Cumul Sortie B12 TEMCI : | R48: =SUMIF(C32:C45,"Sortie",N32:N45) -> 0

Sheet Synthèses Stocks
B1: SAEPP | S1: Menu | V1: =TEXT(TODAY(),"dd/mm/yyyy") -> 05/01/2026
R2: Année: | S2: 2025
B3: FICHE DE SUIVI DE STOCKS | E3: SYNTHESES - ETATS DE STOCKS AU 05/01/2026 | R3: MOIS : | S3: =TEXT(TODAY(),"mmmm") -> janvier
B5: BOUTEILLES PI | G5: B6 | J5: INVENTAIRE | N5: B12 | R5: INVENTAIRE
B6: DATE | C6: TYPES DE STOCKS | D6: DESTINATION / PROVENANCE | E6: QUANTITE STOCK INITIAL | F6: ENTREE EN STOCKS | G6: SORTIE DE STOCKS | H6: QUANTITE STOCK FINAL | J6: INVENTAIRE | K6: ECART | M6: QUANTITE STOCK INITIAL | N6: ENTREE EN STOCKS | O6: SORTIE DE STOCKS | P6: QUANTITE STOCK FINAL | R6: INVENTAIRE | S6: ECART | U6: JUSTIFICATIF D'ÉCART
K8: =IF(J8="","",J8-H8) | S8: =IF(R8="","",R8-P8)
B9: 45932 | C9: BOUTEILLES NEUVES | E9: ='Btles Neuve _ DV'!J10 -> 0 | F9: =+'Btles Neuve _ DV'!G22 -> 2240 | G9: =+'Btles Neuve _ DV'!G23 -> 2100 | H9: =+E9+F9-G9 -> 140 | J9: {=INDEX('Btles Neuve _ DV'!J9:J20, MAX(IF('Btles Neuve _ DV'!J9:J20<>"", ROW('Btles Neuve _ DV'!J9:J20)-ROW('Btles Neuve _ DV'!J9)+1)))} -> 140 | K9: =IF(J9="","",J9-H9) -> 0 | M9: =+'Btles Neuve _ DV'!Q10 -> 0 | N9: =+'Btles Neuve _ DV'!R22 -> 0 | O9: =+'Btles Neuve _ DV'!R23 -> 0 | P9: =+M9+N9-O9 -> 0 | R9: {=INDEX('Btles Neuve _ DV'!Q9:Q20, MAX(IF('Btles Neuve _ DV'!Q9:Q20<>"", ROW('Btles Neuve _ DV'!Q9:Q20)-ROW('Btles Neuve _ DV'!Q9)+1)))} -> 0 | S9: =IF(R9="","",R9-P9) -> 0
C10: BOUTEILLES CONSIGNES | E10: ='Consigne _ CE'!J10 -> 1685 | F10: ='Consigne _ CE'!G24 -> 2100 | G10: ='Consigne _ CE'!G25 -> 1400 | H10: 2385 | J10: {=INDEX('Consigne _ CE'!J9:J22, MAX(IF('Consigne _ CE'!J9:J22<>"", ROW('Consigne _ CE'!J9:J22)-ROW('Consigne _ CE'!J9)+1)))} -> 2385 | K10: =IF(J10="","",J10-H10) -> 0 | M10: ='Consigne _ CE'!Q10 -> 35 | N10: ='Consigne _ CE'!R24 -> 0 | O10: ='Consigne _ CE'!R25 -> 0 | P10: 35 | R10: {=INDEX('Consigne _ CE'!Q9:Q22, MAX(IF('Consigne _ CE'!Q9:Q22<>"", ROW('Consigne _ CE'!Q9:Q22)-ROW('Consigne _ CE'!Q9)+1)))} -> 35 | S10: =IF(R10="","",R10-P10) -> 0
C11: BOUTEILLES STOCK OUTIL | E11: ='PARC BOUTEILLES CE (PI & TEMCI)'!J10 -> 10965 | F11: ='PARC BOUTEILLES CE (PI & TEMCI)'!G25 -> 0 | G11: ='PARC BOUTEILLES CE (PI & TEMCI)'!G26 -> 770 | H11: =+E11+F11-G11 -> 10195 | J11: {=INDEX('PARC BOUTEILLES CE (PI & TEMCI)'!J9:J23, MAX(IF('PARC BOUTEILLES CE (PI & TEMCI)'!J9:J23<>"", ROW('PARC BOUTEILLES CE (PI & TEMCI)'!J9:J23)-ROW('PARC BOUTEILLES CE (PI & TEMCI)'!J9)+1)))} -> 10195 | K11: =IF(J11="","",J11-H11) -> 0 | M11: ='PARC BOUTEILLES CE (PI & TEMCI)'!Q10 -> 5267 | N11: ='PARC BOUTEILLES CE (PI & TEMCI)'!R25 -> 0 | O11: ='PARC BOUTEILLES CE (PI & TEMCI)'!R26 -> 70 | P11: 5197 | R11: {=INDEX('PARC BOUTEILLES CE (PI & TEMCI)'!Q9:Q23, MAX(IF('PARC BOUTEILLES CE (PI & TEMCI)'!Q9:Q23<>"", ROW('PARC BOUTEILLES CE (PI & TEMCI)'!Q9:Q23)-ROW('PARC BOUTEILLES CE (PI & TEMCI)'!Q9)+1)))} -> 5197 | S11: =IF(R11="","",R11-P11) -> 0
C12: BOUTEILLES HS | E12: ='Btles HS _ DV'!J10 -> 16301 | F12: ='Btles HS _ DV'!G23 -> 770 | G12: ='Btles HS _ DV'!G24 -> 0 | H12: =+E12+F12-G12 -> 17071 | J12: {=INDEX('Btles HS _ DV'!J9:J21, MAX(IF('Btles HS _ DV'!J9:J21<>"", ROW('Btles HS _ DV'!J9:J21)-ROW('Btles HS _ DV'!J9)+1)))} -> 17071 | K12: =IF(J12="","",J12-H12) -> 0 | M12: ='Btles HS _ DV'!Q10 -> 1128 | N12: ='Btles HS _ DV'!R23 -> 70 | O12: ='Btles HS _ DV'!R24 -> 0 | P12: 1198 | R12: {=INDEX('Btles HS _ DV'!Q9:Q21, MAX(IF('Btles HS _ DV'!Q9:Q21<>"", ROW('Btles HS _ DV'!Q9:Q21)-ROW('Btles HS _ DV'!Q9)+1)))} -> 1198 | S12: =IF(R12="","",R12-P12) -> 0
C13: BOUTEILLES TDS | E13: ='PEINTURE TDS '!J10 -> 0 | F13: ='PEINTURE TDS '!G23 -> 0 | G13: ='PEINTURE TDS '!G24 -> 0 | H13: =+E13+F13-G13 -> 0 | K13: =IF(J13="","",J13-H13) | M13: ='PEINTURE TDS '!Q10 -> 0 | N13: ='PEINTURE TDS '!R23 -> 0 | O13: ='PEINTURE TDS '!R24 -> 0 | P13: =+M13+N13-O13 -> 0 | S13: =IF(R13="","",R13-P13)
S14: =IF(R14="","",R14-P14)
K15: =IF(J15="","",J15-H15) | S15: =IF(R15="","",R15-P15)
G17: TOTAL | H17: =+SUM(H8:H15) -> 29791 | K17: =+SUM(K8:K15) -> 0 | P17: =+SUM(P8:P15) -> 6430 | Q17: =+SUM(Q8:Q15) -> 0 | S17: =+SUM(S8:S15) -> 0
B20: BOUTEILLES TEMCI | G20: B6 | J20: INVENTAIRE | N20: B12 | R20: INVENTAIRE
B21: DATE | C21: TYPES DE STOCKS | D21: DESTINATION / PROVENANCE | E21: QUANTITE STOCK INITIAL | F21: ENTREE EN STOCKS | G21: SORTIE DE STOCKS | H21: QUANTITE STOCK FINAL | J21: INVENTAIRE | K21: ECART | M21: QUANTITE STOCK INITIAL | N21: ENTREE EN STOCKS | O21: SORTIE DE STOCKS | P21: QUANTITE STOCK FINAL | R21: INVENTAIRE | S21: ECART | U21: JUSTIFICATIF D'ÉCART
K23: =IF(J23="","",J23-H23) | S23: =IF(R23="","",R23-P23)
B24: 45932 | C24: BOUTEILLES NEUVES | E24: =+'Btles Neuve _ DV'!J32 -> 24687 | F24: =+'Btles Neuve _ DV'!G42 -> 0 | G24: =+'Btles Neuve _ DV'!G43 -> 0 | H24: =+E24+F24-G24 -> 24687 | J24: {=INDEX('Btles Neuve _ DV'!J31:J40, MAX(IF('Btles Neuve _ DV'!J31:J40<>"", ROW('Btles Neuve _ DV'!J31:J40)-ROW('Btles Neuve _ DV'!J31)+1)))} -> 24687 | K24: =IF(J24="","",J24-H24) -> 0 | M24: =+'Btles Neuve _ DV'!Q32 -> 2161 | N24: =+'Btles Neuve _ DV'!R42 -> 0 | O24: =+'Btles Neuve _ DV'!R43 -> 0 | P24: =+M24+N24-O24 -> 2161 | R24: {=INDEX('Btles Neuve _ DV'!Q31:Q40, MAX(IF('Btles Neuve _ DV'!Q31:Q40<>"", ROW('Btles Neuve _ DV'!Q31:Q40)-ROW('Btles Neuve _ DV'!Q31)+1)))} -> 2161 | S24: =IF(R24="","",R24-P24) -> 0
C25: BOUTEILLES CONSIGNES | E25: ='Consigne _ CE'!J34 -> 1260 | F25: ='Consigne _ CE'!G46 -> 0 | G25: ='Consigne _ CE'!G47 -> 105 | H25: 1504 | J25: 1504 | K25: =IF(J25="","",J25-H25) -> 0 | M25: ='Consigne _ CE'!Q34 -> 315 | N25: ='Consigne _ CE'!R46 -> 0 | O25: ='Consigne _ CE'!R47 -> 0 | P25: 175 | R25: 175 | S25: =IF(R25="","",R25-P25) -> 0
C26: BOUTEILLES STOCK OUTIL | E26: ='PARC BOUTEILLES CE (PI & TEMCI)'!J35 -> 9759 | F26: ='PARC BOUTEILLES CE (PI & TEMCI)'!G52 -> 0 | G26: ='PARC BOUTEILLES CE (PI & TEMCI)'!G53 -> 266 | H26: =+E26+F26-G26 -> 9493 | J26: {=INDEX('PARC BOUTEILLES CE (PI & TEMCI)'!J34:J50, MAX(IF('PARC BOUTEILLES CE (PI & TEMCI)'!J34:J50<>"", ROW('PARC BOUTEILLES CE (PI & TEMCI)'!J34:J50)-ROW('PARC BOUTEILLES CE (PI & TEMCI)'!J34)+1)))} -> 9493 | K26: =IF(J26="","",J26-H26) -> 0 | M26: ='PARC BOUTEILLES CE (PI & TEMCI)'!Q35 -> 2111 | N26: ='PARC BOUTEILLES CE (PI & TEMCI)'!R52 -> 0 | O26: ='PARC BOUTEILLES CE (PI & TEMCI)'!R53 -> 252 | P26: =+M26+N26-O26 -> 1859 | R26: {=INDEX('PARC BOUTEILLES CE (PI & TEMCI)'!Q34:Q50, MAX(IF('PARC BOUTEILLES CE (PI & TEMCI)'!Q34:Q50<>"", ROW('PARC BOUTEILLES CE (PI & TEMCI)'!Q34:Q50)-ROW('PARC BOUTEILLES CE (PI & TEMCI)'!Q34)+1)))} -> 1859 | S26: =IF(R26="","",R26-P26) -> 0
C27: BOUTEILLES HS | E27: ='Btles HS _ DV'!J33 -> 1708 | F27: ='Btles HS _ DV'!G44 -> 266 | G27: ='Btles HS _ DV'!G45 -> 0 | H27: =+E27+F27-G27 -> 1974 | J27: {=INDEX('Btles HS _ DV'!J32:J42, MAX(IF('Btles HS _ DV'!J32:J42<>"", ROW('Btles HS _ DV'!J32:J42)-ROW('Btles HS _ DV'!J32)+1)))} -> 1974 | K27: =IF(J27="","",J27-H27) -> 0 | M27: ='Btles HS _ DV'!Q33 -> 925 | N27: ='Btles HS _ DV'!R44 -> 252 | O27: ='Btles HS _ DV'!R45 -> 0 | P27: =+M27+N27-O27 -> 1177 | R27: {=INDEX('Btles HS _ DV'!Q32:Q42, MAX(IF('Btles HS _ DV'!Q32:Q42<>"", ROW('Btles HS _ DV'!Q32:Q42)-ROW('Btles HS _ DV'!Q32)+1)))} -> 1177 | S27: =IF(R27="","",R27-P27) -> 0
C28: BOUTEILLES TDS | E28: ='PEINTURE TDS '!J33 -> 0 | F28: ='PEINTURE TDS '!G47 -> 0 | G28: ='PEINTURE TDS '!G48 -> 0 | H28: =+E28+F28-G28 -> 0 | K28: =IF(J28="","",J28-H28) | M28: ='PEINTURE TDS '!Q33 -> 0 | N28: ='PEINTURE TDS '!R47 -> 0 | O28: ='PEINTURE TDS '!R48 -> 0 | P28: =+M28+N28-O28 -> 0 | S28: =IF(R28="","",R28-P28)
K29: =IF(J29="","",J29-H29) | S29: =IF(R29="","",R29-P29)
K30: =IF(J30="","",J30-H30) | S30: =IF(R30="","",R30-P30)
G32: TOTAL | H32: =+SUM(H23:H30) -> 37658 | K32: =+SUM(K23:K30) -> 0 | P32: =+SUM(P23:P30) -> 5372 | Q32: =+SUM(Q23:Q30) -> 0 | S32: =+SUM(S23:S30) -> 0
B35: BOUTEILLES VIVO ENERGY | G35: B6 | J35: INVENTAIRE | N35: B12 | R35: INVENTAIRE
B36: DATE | C36: TYPES DE STOCKS | D36: DESTINATION / PROVENANCE | E36: QUANTITE STOCK INITIAL | F36: ENTREE EN STOCKS | G36: SORTIE DE STOCKS | H36: QUANTITE STOCK FINAL | J36: INVENTAIRE | K36: ECART | M36: QUANTITE STOCK INITIAL | N36: ENTREE EN STOCKS | O36: SORTIE DE STOCKS | P36: QUANTITE STOCK FINAL | R36: INVENTAIRE | S36: ECART | U36: JUSTIFICATIF D'ÉCART
K38: =IF(J38="","",J38-H38) | S38: =IF(R38="","",R38-P38)
B39: 45932 | C39: BOUTEILLES NEUVES | E39: =+'Btles Neuve _ DV'!J51 -> 0 | F39: ='Btles Neuve _ DV'!G62 -> 0 | G39: ='Btles Neuve _ DV'!G63 -> 0 | H39: =+E39+F39-G39 -> 0 | J39: {=INDEX('Btles Neuve _ DV'!J50:J60, MAX(IF('Btles Neuve _ DV'!J50:J60<>"", ROW('Btles Neuve _ DV'!J50:J60)-ROW('Btles Neuve _ DV'!J50)+1)))} -> 0 | K39: =IF(J39="","",J39-H39) -> 0 | P39: =+M39+N39-O39 -> 0 | S39: =IF(R39="","",R39-P39)
C40: BOUTEILLES CONSIGNES | H40: =+E40+F40-G40 -> 0 | K40: =IF(J40="","",J40-H40) | P40: =+M40+N40-O40 -> 0 | S40: =IF(R40="","",R40-P40)
C41: BOUTEILLES STOCK OUTIL | E41: ='STOCK OUTILS VIVO'!J10 -> 1103 | F41: ='STOCK OUTILS VIVO'!G20 -> 0 | G41: ='STOCK OUTILS VIVO'!G21 -> 0 | H41: =+E41+F41-G41 -> 1103 | J41: {=INDEX('STOCK OUTILS VIVO'!J9:J18, MAX(IF('STOCK OUTILS VIVO'!J9:J18<>"", ROW('STOCK OUTILS VIVO'!J9:J18)-ROW('STOCK OUTILS VIVO'!J9)+1)))} -> 1103 | K41: =IF(J41="","",J41-H41) -> 0 | M41: ='STOCK OUTILS VIVO'!Q10 -> 34 | N41: ='STOCK OUTILS VIVO'!R20 -> 0 | O41: ='STOCK OUTILS VIVO'!R21 -> 0 | P41: 34 | R41: {=INDEX('STOCK OUTILS VIVO'!Q9:Q18, MAX(IF('STOCK OUTILS VIVO'!Q9:Q18<>"", ROW('STOCK OUTILS VIVO'!Q9:Q18)-ROW('STOCK OUTILS VIVO'!Q9)+1)))} -> 34 | S41: =IF(R41="","",R41-P41) -> 0 | U41: 175 Bouteilles B6 sorties au shift de nuit sur le BT N°18926
C42: BOUTEILLES HS | H42: =+E42+F42-G42 -> 0 | K42: =IF(J42="","",J42-H42) | P42: =+M42+N42-O42 -> 0 | S42: =IF(R42="","",R42-P42) | U42: 280 Bouteilles B12 sorties au shift de nuit sur le BT N°18926
C43: BOUTEILLES TDS | H43: =+E43+F43-G43 -> 0 | K43: =IF(J43="","",J43-H43) | P43: =+M43+N43-O43 -> 0 | S43: =IF(R43="","",R43-P43) | U43: -1 Bouteille B12 Ecart non justifié
H44: =+E44+F44-G44 -> 0 | K44: =IF(J44="","",J44-H44) | P44: =+M44+N44-O44 -> 0 | S44: =IF(R44="","",R44-P44)
K45: =IF(J45="","",J45-H45) | S45: =IF(R45="","",R45-P45)
G47: TOTAL | H47: =+SUM(H38:H45) -> 1103 | K47: =+SUM(K38:K45) -> 0 | P47: =+SUM(P38:P45) -> 34 | Q47: =+SUM(Q38:Q45) -> 0 | S47: =+SUM(S38:S45) -> 0
